Workbook
Name Valuation_Date: Inputs!$D$10
Name Price: Inputs!$D$11
Name Shares_Diluted: Inputs!$D$15
Name Base_FYE: Inputs!$D$16
Name Midyear: Inputs!$D$17
Name Days_Per_Year: Inputs!$D$18
Name Beta_Unlevered: Inputs!$D$136
Name Rf_Source: Inputs!$D$158
Name CAPM_Method: Inputs!$D$160
Name Kd_Method: Inputs!$D$164
Name Terminal_Method: Inputs!$D$171
Name Terminal_Growth: Inputs!$D$172
Name Exit_Multiple: Inputs!$D$173
Name DA_Method: Inputs!$D$180
Name Capex_Mode: Inputs!$D$181
Name Rf: WACC!$D$12
Name Ke: WACC!$D$30
Name Tax_Rate: WACC!$D$44
Name WACC: WACC!$D$54
Name Enterprise_Value: DCF!$D$30
Name Equity_Value: DCF!$D$52
Name DCF_Per_Share: DCF!$D$54
Name DDM_Per_Share: DDM!$D$25
Name Blended_Value: Summary!$D$14
Name Master_Check: Checks!$D$40

Sheet Cover
B2: Misr Fertilizers Production Company (MFPC.CA): Valuation workbook
B3: Discounted cash flow valuation with cross-checks. Analytical only; not investment advice. Inputs are as entered; macro rates from the frozen snapshot listed on Sources.
B4: Blue = hardcoded input | Black = formula
B6: Valuation
D7: Value | F7: Notes
B8: Company | D8: Misr Fertilizers Production Company
B9: Ticker | D9: MFPC.CA
B10: Valuation date | C10: date | D10: =Inputs!$D$10
B11: Share price | C11: EGP | D11: =Inputs!$D$11
B12: Price date | C12: date | D12: =Inputs!$D$12
B13: Prepared by | D13: Ahmed Wael Metwally
B14: Rates snapshot | D14: seed-2026-09-23 | F14: Frozen 2026-09-24T07:01:32.500Z
B15: Terminal method | D15: gordon
B16: Master check (all checks TRUE) | D16: =Checks!$D$40
B18: Contents
D19: Sheet | F19: Notes
B20: Cover | D20: Cover
B21: Summary | D21: Summary
B22: Inputs | D22: Inputs
B23: Sources | D23: Sources
B24: Historical | D24: Historical
B25: Normalization | D25: Normalization
B26: Operating Model | D26: Operating Model
B27: WACC | D27: WACC
B28: DCF | D28: DCF
B29: USD Check | D29: USD Check
B30: DDM | D30: DDM
B31: Comps Precedents SOTP | D31: Comps Precedents SOTP
... B34: Checks | D34: Checks

Sheet Summary
B2: MOPCO: Summary
B3: Value per share by method, blend weights, implied upside and key assumptions. Values are live formulas from the model sheets.
B4: Blue = hardcoded input | Black = formula
B6: Value per share by method
D7: Value per share | E7: Entered weight | F7: Effective weight | G7: Notes
B8: DCF (FCFF) | C8: EGP | D8: =DCF!$D$54 | E8: =Inputs!$D$241 | F8: =IF(AND(ISNUMBER($D$8),$E$8>0),$E$8/SUMPRODUCT(ISNUMBER($D$8:$D$12)*($E$8:$E$12)),0)
B9: Dividend discount model (two-stage) | C9: EGP | D9: =DDM!$D$25 | E9: =Inputs!$D$242 | F9: =IF(AND(ISNUMBER($D$9),$E$9>0),$E$9/SUMPRODUCT(ISNUMBER($D$8:$D$12)*($E$8:$E$12)),0)
B10: Trading comparables (median EV/EBITDA) | C10: EGP | D10: ="n/a" | E10: =Inputs!$D$243 | F10: =IF(AND(ISNUMBER($D$10),$E$10>0),$E$10/SUMPRODUCT(ISNUMBER($D$8:$D$12)*($E$8:$E$12)),0) | G10: Excluded when no inputs are entered.
B11: Precedent transactions (median EV/EBITDA) | C11: EGP | D11: ="n/a" | E11: =Inputs!$D$244 | F11: =IF(AND(ISNUMBER($D$11),$E$11>0),$E$11/SUMPRODUCT(ISNUMBER($D$8:$D$12)*($E$8:$E$12)),0) | G11: Excluded when no inputs are entered.
B12: Sum of the parts | C12: EGP | D12: ="n/a" | E12: =Inputs!$D$245 | F12: =IF(AND(ISNUMBER($D$12),$E$12>0),$E$12/SUMPRODUCT(ISNUMBER($D$8:$D$12)*($E$8:$E$12)),0) | G12: Excluded when no inputs are entered.
B13: Entered weights sum | C13: % | E13: =SUM($E$8:$E$12)
B14: Blended value per share | C14: EGP | D14: =SUMPRODUCT($D$8:$D$12,$F$8:$F$12)
B15: Share price (2026-07-01) | C15: EGP | D15: =Inputs!$D$11
B16: Implied upside | C16: % | D16: =$D$14/$D$15-1
B17: Band | D17: =IF(ABS($D$16)<=Inputs!$D$249,"In line with market price",IF($D$16>0,"Above market price","Below market price"))
B19: Implied multiples (DCF)
D20: Value | G20: Notes
B21: EV / normalized EBITDA FY2025A | C21: x | D21: =DCF!$D$59
B22: EV / EBITDA FY2026E | C22: x | D22: =DCF!$D$60
B23: P/E FY2025A | C23: x | D23: =DCF!$D$61
B24: P/E FY2026E | C24: x | D24: =DCF!$D$62
B25: PV of terminal value / EV | C25: % | D25: =DCF!$D$31
B27: Key assumptions
D28: Value | G28: Notes
B29: WACC | C29: % | D29: =WACC!$D$54
B30: Cost of equity | C30: % | D30: =WACC!$D$30
B31: Risk-free rate | C31: % | D31: =WACC!$D$12 | G31: eg.bond10ySecondary, as of 2026-05-21, status stale
B32: Levered beta | C32: x | D32: =WACC!$D$21
B33: Terminal growth | C33: % | D33: =Inputs!$D$172
B34: Terminal method | D34: =Inputs!$D$171
B35: Employee and board distributions, % of prior-year profit | C35: % | D35: =Inputs!$D$201*Inputs!$D$200
B37: Football field (value per share)
D38: Low | E38: Mid | F38: High | G38: Notes
B39: DCF (FCFF): WACC ± 1 step × g ± 1 step | C39: EGP | D39: =MIN(Sensitivity!$E$22:$G$24) | E39: =DCF!$D$54 | F39: =MAX(Sensitivity!$E$22:$G$24)
B40: Dividend discount model | C40: EGP | D40: =MIN(DDM!$D$25,DDM!$D$27) | E40: =DDM!$D$25 | F40: =MAX(DDM!$D$25,DDM!$D$27)
B41: Scenarios (Bear to Bull) | C41: EGP | D41: =Scenarios!$D$60 | E41: =Scenarios!$D$20 | F41: =Scenarios!$D$134
B42: Monte Carlo P5 to P95 (engine output, seed 20260923) | C42: EGP | D42: =Inputs!$D$294 | E42: =Inputs!$D$295 | F42: =Inputs!$D$296 | G42: Simulation is run by the engine; not reproduced in the workbook
B43: Share price | C43: EGP | E43: =Inputs!$D$11

Sheet Inputs
B2: MOPCO: Inputs
B3: Every hardcoded number used by the workbook. Company data from the audited statements; rates from the frozen snapshot; assumptions as set by the analyst.
B4: Blue = hardcoded input | Black = formula
B6: Company and timeline
D7: Value | J7: Notes
B8: Company | D8: Misr Fertilizers Production Company | J8: Sourced fact
B9: Ticker | D9: MFPC.CA | J9: Sourced fact
B10: Valuation date | C10: date | D10: 46205 | J10: Analyst assumption. Mandatory.
B11: Share price | C11: EGP | D11: 36 | J11: Sourced fact: EFG Hermes research page (user input; EGX has no free official price feed)
B12: Price date | C12: date | D12: 46204 | J12: Sourced fact. Mandatory.
B13: Basic shares | C13: shares | D13: 2868140263 | J13: Sourced fact. After the 2025 bonus issue; EPS for both years computed on this count.
B14: Dilutive items | C14: shares | D14: 0 | J14: None disclosed
B15: Diluted shares | C15: shares | D15: =$D$13+$D$14
B16: Base fiscal year end | C16: date | D16: 46022 | J16: Sourced fact: latest audited year end
B17: Mid-year discounting (1 = on, 0 = off) | C17: flag | D17: 1 | J17: Analyst assumption
B18: Days per year (unit conversion) | C18: days | D18: 365 | J18: Unit conversion for years from valuation date and working-capital days
B19: Projection years | C19: years | D19: 5 | J19: Structural: one column per projection year
B21: Income statement
C22: EGP | D22: 2024A | E22: 2025A | J22: Notes
B23: Net sales | C23: EGP | D23: 19650320858 | E23: 26844075576 | J23: Sourced fact: audited statements
B24: of which export sales | C24: EGP | D24: 15069860384 | E24: 21466612052 | J24: Sourced fact: audited statements
B25: Cost of sales | C25: EGP | D25: -10802884928 | E25: -13307578650 | J25: Sourced fact: audited statements
B26: Gross profit | C26: EGP | D26: 8847435930 | E26: 13536496926 | J26: Sourced fact: audited statements
B27: Other income | C27: EGP | D27: 173469168 | E27: 273707416 | J27: Sourced fact: audited statements
B28: of which provisions no longer required | C28: EGP | D28: 19299728 | E28: 160216876 | J28: Sourced fact: audited statements
B29: Selling and marketing | C29: EGP | D29: -531853525 | E29: -526930783 | J29: Sourced fact: audited statements
B30: General and administrative | C30: EGP | D30: -591253894 | E30: -648542515 | J30: Sourced fact: audited statements
B31: Capital gains | C31: EGP | D31: 3619907 | E31: 13156038 | J31: Sourced fact: audited statements
B32: Other expenses | C32: EGP | D32: -233949210 | E32: -44594149 | J32: Sourced fact: audited statements
B33: Impairment reversal | C33: EGP | D33: 310962888 | E33: 0 | J33: Sourced fact: audited statements
B34: ECL reversal / (charge) | C34: EGP | D34: -390502424 | E34: 357037587 | J34: Sourced fact: audited statements
... B53: EPS as reported | C53: EGP | D53: 5.27 | E53: 3.94 | J53: Sourced fact: audited statements
B55: Balance sheet
C56: EGP | D56: 2024A | E56: 2025A | J56: Notes
B57: Fixed assets and projects under construction | C57: EGP | D57: 34632006997 | E57: 38192488081 | J57: Sourced fact: audited statements
B58: Other assets and projects | C58: EGP | D58: 68215075 | E58: 79638512 | J58: Sourced fact: audited statements
B59: Right-of-use assets | C59: EGP | D59: 88041967 | E59: 72034336 | J59: Sourced fact: audited statements
B60: Goodwill | C60: EGP | D60: 0 | E60: 0 | J60: Sourced fact: audited statements
B61: Associates (equity method) | C61: EGP | D61: 2407651 | E61: 2424170 | J61: Sourced fact: audited statements
B62: Amortized-cost investments (non-current) | C62: EGP | D62: 5562646156 | E62: 10659141927 | J62: Sourced fact: audited statements
...

Sheet Sources
B2: MOPCO: Sources
B3: Every registry value in the frozen rates snapshot seed-2026-09-23, with source, date and status; and the source of the company data.
B4: Blue = hardcoded input | Black = formula
B6: Company data
D7: Value | O7: Notes
B8: Financial statements | D8: Audited financial statements for the year ended 31 December 2025 (with FY2024 comparatives). All amounts in EGP.
B9: Auditor | D9: Crowe - Dr. A. M. Hegazy & Co.
B10: Audit report date | C10: date | D10: 46090
B11: Share price source | D11: EFG Hermes research page (user input; EGX has no free official price feed)
B12: Associate | D12: 25% stake in Damietta Green Ammonia, accounted for by the equity method. | O12: Audited FY2025 financial statements
B13: Capital commitments | D13: Outstanding capital commitments: EGP 939m + USD 4m + EUR 101m. | O13: Audited FY2025 financial statements
B14: Expansion project | D14: Urea/ammonia expansion project spend to date approximately EGP 5.9bn. | O14: Audited FY2025 financial statements
B15: Employee profit share | D15: Articles of association pay 10% of cash dividends to employees, capped at annual salaries. | O15: Audited FY2025 financial statements
B16: Borrowings | D16: Bank borrowings are nil at 31-Dec-2025 and 31-Dec-2024. Interest-bearing debt consists of lease liabilities only. | O16: Audited FY2025 financial statements
B17: Historical years | D17: FY2021 to FY2023 not supplied as audited data and left empty. | O17: Owner instruction
B18: Segments | D18: Urea / ammonia segment figures are in the segment note of the audited statements but were not supplied in the fixture data; SOTP requires user entry. | O18: Owner instruction
B20: Rates registry (snapshot seed-2026-09-23)
C21: Label | D21: Id | E21: Value | F21: Unit | G21: Nature | H21: Source | I21: URL | J21: As of | K21: Method | L21: Status | M21: Used in model | N21: Flag | O21: Notes
B22: CBE overnight deposit rate | D22: cbe.overnightDeposit | E22: 0.19 | F22: pct | G22: official | H22: Central Bank of Egypt | I22: https://www.cbe.org.eg/en/ | J22: 46254 | K22: manual | L22: stale | M22: No | N22: =IF(AND($M$22="Yes",$L$22<>"ok"),"Flagged: "&$L$22,"") | O22: MPC 20-Aug-2026: rates held. Next MPC 24-Sep-2026; must be re-verified after that meeting.
B23: CBE overnight lending rate | D23: cbe.overnightLending | E23: 0.2 | F23: pct | G23: official | H23: Central Bank of Egypt | I23: https://www.cbe.org.eg/en/ | J23: 46254 | K23: manual | L23: stale | M23: No | N23: =IF(AND($M$23="Yes",$L$23<>"ok"),"Flagged: "&$L$23,"")
B24: CBE main operation rate | D24: cbe.mainOperation | E24: 0.195 | F24: pct | G24: official | H24: Central Bank of Egypt | I24: https://www.cbe.org.eg/en/ | J24: 46254 | K24: manual | L24: stale | M24: No | N24: =IF(AND($M$24="Yes",$L$24<>"ok"),"Flagged: "&$L$24,"")
B25: CBE discount rate | D25: cbe.discountRate | E25: 0.195 | F25: pct | G25: official | H25: Central Bank of Egypt | I25: https://www.cbe.org.eg/en/monetary-policy/mpc-meetings-schedule | J25: 46254 | K25: manual | L25: stale | M25: No | N25: =IF(AND($M$25="Yes",$L$25<>"ok"),"Flagged: "&$L$25,"")
B26: CBE inflation target | D26: cbe.inflationTarget | E26: 7% ±2pp, Q4 2026 (CBE guidance now points to 2H 2027) | F26: text | G26: official | H26: Central Bank of Egypt | I26: https://www.cbe.org.eg/en/monetary-policy/inflation-target | J26: 46254 | K26: manual | L26: ok | M26: No | N26: =IF(AND($M$26="Yes",$L$26<>"ok"),"Flagged: "&$L$26,"")
B27: CBE inflation target (point, for USD-check inflation fade) | D27: cbe.inflationTargetPoint | E27: 0.07 | F27: pct | G27: official | H27: Central Bank of Egypt | I27: https://www.cbe.org.eg/en/monetary-policy/inflation-target | J27: 46254 | K27: manual | L27: ok | M27: No | N27: =IF(AND($M$27="Yes",$L$27<>"ok"),"Flagged: "&$L$27,"") | O27: Point of the 7% ±2pp target. The CBE homepage on 23-Sep-2026 shows "7.0% (±2 percentage points) on average in 2026 Q4".
B28: CBE MPC meeting dates | D28: cbe.mpcCalendar | E28: 2026-08-20, 2026-09-24 | F28: date_list | G28: official | H28: Central Bank of Egypt, MPC meetings schedule | I28: https://www.cbe.org.eg/en/monetary-policy/mpc-meetings-schedule | J28: 46288 | K28: manual | L28: unconfirmed | M28: No | N28: =IF(AND($M$28="Yes",$L$28<>"ok"),"Flagged: "&$L$28,"") | O28: 20-Aug-2026 confirmed by the CBE homepage news item "MPC decides to keep key policy rates unchanged". 24-Sep-2026 from owner research. The CBE schedule page renders dates with JavaScript and could not be read on 23-Sep-2026; remaining 2026 and 2027 dates are unconfirmed.
B29: Urban headline CPI inflation, y/y | D29: eg.cpiUrbanHeadline | E29: 0.145 | F29: pct | G29: official | H29: CAPMAS (reported by CBE) | I29: https://www.cbe.org.eg/en/monetary-policy/inflation | J29: 46265 | K29: manual | L29: ok | M29: No | N29: =IF(AND($M$29="Yes",$L$29<>"ok"),"Flagged: "&$L$29,"") | O29: August 2026, released 10-Sep-2026.
B30: Core CPI inflation, y/y | D30: eg.cpiCore | E30: 0.149 | F30: pct | G30: official | H30: Central Bank of Egypt | I30: https://www.cbe.org.eg/en/monetary-policy/inflation | J30: 46265 | K30: manual | L30: ok | M30: No | N30: =IF(AND($M$30="Yes",$L$30<>"ok"),"Flagged: "&$L$30,"")
B31: Nationwide CPI inflation, y/y | D31: eg.cpiNationwide | E31: 0.127 | F31: pct | G31: official | H31: CAPMAS | I31: TO_VERIFY | J31: 46265 | K31: manual | L31: ok | M31: No | N31: =IF(AND($M$31="Yes",$L$31<>"ok"),"Flagged: "&$L$31,"")
B32: USD/EGP | D32: eg.usdEgp | E32: 51.9 | F32: EGP_per_USD | G32: market_quote | H32: Market close (owner research) | I32: TO_VERIFY | J32: 46286 | K32: manual | L32: ok | M32: Yes | N32: =IF(AND($M$32="Yes",$L$32<>"ok"),"Flagged: "&$L$32,"") | O32: Approximate market close 21-Sep-2026. The Worker replaces it with the CBE official rate (https://www.cbe.org.eg/en/economic-research/statistics/cbe-exchange-rates).
B33: EGP 10Y government bond, secondary-market YTM | D33: eg.bond10ySecondary | E33: 0.2158 | F33: pct | G33: market_quote | H33: Cbonds | I33: TO_VERIFY | J33: 46163 | K33: manual | L33: stale | M33: Yes | N33: =IF(AND($M$33="Yes",$L$33<>"ok"),"Flagged: "&$L$33,"") | O33: Last quote available to the owner is 21-May-2026. Manual refresh required.
B34: EGP T-bond auction, 3y fixed coupon (accepted weighted average yield) | D34: eg.tbondAuction.3y | E34: 0.23147 | F34: pct | G34: official | H34: Central Bank of Egypt, T-bond auction results | I34: https://www.cbe.org.eg/en/auctions/egp-t-bonds-fixed-coupon | J34: 46216 | K34: manual | L34: stale | M34: No | N34: =IF(AND($M$34="Yes",$L$34<>"ok"),"Flagged: "&$L$34,"") | O34: Auction of 13-Jul-2026. Recent auctions were 2Y and 3Y only.
B35: US Treasury 10Y | D35: us.treasury10y | E35: 0.051 | F35: pct | G35: market_quote | H35: US Treasury (intraday, owner research) | I35: https://home.treasury.gov/resource-center/data-chart-center/interest-rates/TextView?type=daily_treasury_yield_curve | J35: 46288 | K35: manual | L35: ok | M35: Yes | N35: =IF(AND($M$35="Yes",$L$35<>"ok"),"Flagged: "&$L$35,"") | O35: Approximate intraday level 23-Sep-2026. The Worker replaces it with the Treasury daily par yield (10-year).
B36: Egypt sovereign rating, Moody's | D36: eg.rating.moodys | E36: Caa1 (positive) | F36: rating | G36: official | H36: Moody's Ratings | I36: https://ratings.moodys.com/ratings-news/462631 | J36: 46115 | K36: manual | L36: ok | M36: No | N36: =IF(AND($M$36="Yes",$L$36<>"ok"),"Flagged: "&$L$36,"")
B37: Egypt sovereign rating, S&P | D37: eg.rating.sp | E37: B (stable) | F37: rating | G37: official | H37: S&P Global Ratings press release; secondary: Ahram Online 11-Apr-2026 | I37: TO_VERIFY | J37: 46123 | K37: manual | L37: ok | M37: No | N37: =IF(AND($M$37="Yes",$L$37<>"ok"),"Flagged: "&$L$37,"") | O37: Affirmation at B/B, stable. Candidate primary URL from a search index, not opened (HTTP 403 on 23-Sep-2026): https://www.spglobal.com/ratings/en/regulatory/article/-/view/type/HTML/id/3544107. The pre-v2 engine showed "B-", which is wrong.
B38: Egypt sovereign rating, Fitch | D38: eg.rating.fitch | E38: B (stable) | F38: rating | G38: official | H38: Fitch Ratings (via Ahram Online, 11-Oct-2025) | I38: https://english.ahram.org.eg/News/554751.aspx | J38: 45941 | K38: manual | L38: unconfirmed | M38: No | N38: =IF(AND($M$38="Yes",$L$38<>"ok"),"Flagged: "&$L$38,"") | O38: Last confirmed action Oct-2025. No 2026 Fitch action found on 23-Sep-2026; fitchratings.com not checked successfully.
B39: Corporate income tax rate | D39: eg.cit | E39: 0.225 | F39: pct | G39: statutory | H39: Income Tax Law 91/2005 | I39: TO_VERIFY | J39: 46288 | K39: manual | L39: ok | M39: Yes | N39: =IF(AND($M$39="Yes",$L$39<>"ok"),"Flagged: "&$L$39,"")
B40: Dividend withholding tax, EGX-listed | D40: eg.dividendWht.listed | E40: 0.05 | F40: pct | G40: statutory | H40: Law 151 of 2026 | I40: TO_VERIFY | J40: 46232 | K40: manual | L40: ok | M40: No | N40: =IF(AND($M$40="Yes",$L$40<>"ok"),"Flagged: "&$L$40,"") | O40: Effective 29-Jul-2026.
B41: Dividend withholding tax, unlisted | D41: eg.dividendWht.unlisted | E41: 0.1 | F41: pct | G41: statutory | H41: Law 151 of 2026 | I41: TO_VERIFY | J41: 46232 | K41: manual | L41: ok | M41: No | N41: =IF(AND($M$41="Yes",$L$41<>"ok"),"Flagged: "&$L$41,"")
B42: Participation exemption | D42: eg.participationExemption | E42: 100% exempt if holding ≥25% for ≥2 years | F42: text | G42: statutory | H42: Law 151 of 2026 | I42: TO_VERIFY | J42: 46232 | K42: manual | L42: ok | M42: No | N42: =IF(AND($M$42="Yes",$L$42<>"ok"),"Flagged: "&$L$42,"")
B43: EGX stamp duty per side | D43: eg.stampDuty.perSide | E43: 0.0005 | F43: pct | G43: statutory | H43: Law 151 of 2026 | I43: TO_VERIFY | J43: 46232 | K43: manual | L43: ok | M43: No | N43: =IF(AND($M$43="Yes",$L$43<>"ok"),"Flagged: "&$L$43,"") | O43: 0.05% per side on EGX trades; 0.025% per side for same-session trades; withheld by MCDR from the 29-Jul-2026 session. The pre-v2 engine used 0.125%, which is wrong.
...

Sheet Historical
B2: MOPCO: Historical analysis
B3: Audited years available: 2024, 2025. Earlier years were not supplied and are not filled. N/A where two years are required.
B4: Blue = hardcoded input | Black = formula
B6: Ratios
D7: 2024A | E7: 2025A | G7: Notes
B8: Revenue growth | C8: % | D8: N/A | E8: =Inputs!$E$23/Inputs!$D$23-1
B9: Gross margin | C9: % | D9: =Inputs!$D$26/Inputs!$D$23 | E9: =Inputs!$E$26/Inputs!$E$23
B10: EBITDA margin (reported) | C10: % | D10: =(Inputs!$D$36+Inputs!$D$51+Inputs!$D$52)/Inputs!$D$23 | E10: =(Inputs!$E$36+Inputs!$E$51+Inputs!$E$52)/Inputs!$E$23
B11: Net margin | C11: % | D11: =Inputs!$D$49/Inputs!$D$23 | E11: =Inputs!$E$49/Inputs!$E$23
B12: Effective tax rate | C12: % | D12: =-Inputs!$D$48/Inputs!$D$45 | E12: =-Inputs!$E$48/Inputs!$E$45
B13: Return on equity (year-end equity) | C13: % | D13: =Inputs!$D$49/Inputs!$D$83 | E13: =Inputs!$E$49/Inputs!$E$83
B14: Current ratio | C14: x | D14: =(Inputs!$D$66+Inputs!$D$67+Inputs!$D$68+Inputs!$D$69+Inputs!$D$70+Inputs!$D$71+Inputs!$D$72+Inputs!$D$73+Inputs!$D$74)/(Inputs!$D$90+Inputs!$D$91+Inputs!$D$92+Inputs!$D$93+Inputs!$D$94+Inputs!$D$95+Inputs!$D$96+Inputs!$D$97+Inputs!$D$98+Inputs!$D$99) | E14: =(Inputs!$E$66+Inputs!$E$67+Inputs!$E$68+Inputs!$E$69+Inputs!$E$70+Inputs!$E$71+Inputs!$E$72+Inputs!$E$73+Inputs!$E$74)/(Inputs!$E$90+Inputs!$E$91+Inputs!$E$92+Inputs!$E$93+Inputs!$E$94+Inputs!$E$95+Inputs!$E$96+Inputs!$E$97+Inputs!$E$98+Inputs!$E$99)
B15: Net cash (cash and investments less debt and leases) | C15: EGP | D15: =Inputs!$D$74+Inputs!$D$69+Inputs!$D$68+Inputs!$D$62-Inputs!$D$90-Inputs!$D$91-(Inputs!$D$84+Inputs!$D$85+Inputs!$D$86) | E15: =Inputs!$E$74+Inputs!$E$69+Inputs!$E$68+Inputs!$E$62-Inputs!$E$90-Inputs!$E$91-(Inputs!$E$84+Inputs!$E$85+Inputs!$E$86)
B17: Piotroski F-score (latest year versus prior year; ratios on year-end total assets)
D18: Current | E18: Prior | F18: Score | G18: Notes
B19: Return on assets positive | D19: =Inputs!$E$49/Inputs!$E$75 | F19: =IF($D$19>0,1,0)
B20: Operating cash flow positive | D20: =Inputs!$E$109 | F20: =IF($D$20>0,1,0)
B21: Return on assets improved | D21: =Inputs!$E$49/Inputs!$E$75 | E21: =Inputs!$D$49/Inputs!$D$75 | F21: =IF($D$21>$E$21,1,0)
B22: Cash flow / assets above ROA (accruals) | D22: =Inputs!$E$109/Inputs!$E$75 | E22: =Inputs!$E$49/Inputs!$E$75 | F22: =IF($D$22>$E$22,1,0)
B23: Long-term leverage lower | D23: =(Inputs!$E$84+Inputs!$E$85+Inputs!$E$86)/Inputs!$E$75 | E23: =(Inputs!$D$84+Inputs!$D$85+Inputs!$D$86)/Inputs!$D$75 | F23: =IF($D$23<$E$23,1,0)
B24: Current ratio higher | D24: =(Inputs!$E$66+Inputs!$E$67+Inputs!$E$68+Inputs!$E$69+Inputs!$E$70+Inputs!$E$71+Inputs!$E$72+Inputs!$E$73+Inputs!$E$74)/(Inputs!$E$90+Inputs!$E$91+Inputs!$E$92+Inputs!$E$93+Inputs!$E$94+Inputs!$E$95+Inputs!$E$96+Inputs!$E$97+Inputs!$E$98+Inputs!$E$99) | E24: =(Inputs!$D$66+Inputs!$D$67+Inputs!$D$68+Inputs!$D$69+Inputs!$D$70+Inputs!$D$71+Inputs!$D$72+Inputs!$D$73+Inputs!$D$74)/(Inputs!$D$90+Inputs!$D$91+Inputs!$D$92+Inputs!$D$93+Inputs!$D$94+Inputs!$D$95+Inputs!$D$96+Inputs!$D$97+Inputs!$D$98+Inputs!$D$99) | F24: =IF($D$24>$E$24,1,0)
B25: No equity issued (shares restated; bonus issues are not dilution) | D25: =Inputs!$D$13 | E25: =Inputs!$D$13 | F25: =IF($D$25<=$E$25,1,0)
B26: Gross margin higher | D26: =Inputs!$E$26/Inputs!$E$23 | E26: =Inputs!$D$26/Inputs!$D$23 | F26: =IF($D$26>$E$26,1,0)
B27: Asset turnover higher | D27: =Inputs!$E$23/Inputs!$E$75 | E27: =Inputs!$D$23/Inputs!$D$75 | F27: =IF($D$27>$E$27,1,0)
B28: F-score | C28: of 9 | F28: =SUM($F$19:$F$27)
B30: Altman Z''-EM (Altman 2005, emerging markets)
D31: 2024A | E31: 2025A | G31: Notes
B32: X1 working capital / total assets | C32: x | D32: =((Inputs!$D$66+Inputs!$D$67+Inputs!$D$68+Inputs!$D$69+Inputs!$D$70+Inputs!$D$71+Inputs!$D$72+Inputs!$D$73+Inputs!$D$74)-(Inputs!$D$90+Inputs!$D$91+Inputs!$D$92+Inputs!$D$93+Inputs!$D$94+Inputs!$D$95+Inputs!$D$96+Inputs!$D$97+Inputs!$D$98+Inputs!$D$99))/Inputs!$D$75 | E32: =((Inputs!$E$66+Inputs!$E$67+Inputs!$E$68+Inputs!$E$69+Inputs!$E$70+Inputs!$E$71+Inputs!$E$72+Inputs!$E$73+Inputs!$E$74)-(Inputs!$E$90+Inputs!$E$91+Inputs!$E$92+Inputs!$E$93+Inputs!$E$94+Inputs!$E$95+Inputs!$E$96+Inputs!$E$97+Inputs!$E$98+Inputs!$E$99))/Inputs!$E$75
B33: X2 retained earnings / total assets | C33: x | D33: =Inputs!$D$79/Inputs!$D$75 | E33: =Inputs!$E$79/Inputs!$E$75
B34: X3 EBIT / total assets | C34: x | D34: =Inputs!$D$36/Inputs!$D$75 | E34: =Inputs!$E$36/Inputs!$E$75
B35: X4 book equity / total liabilities | C35: x | D35: =Inputs!$D$83/Inputs!$D$100 | E35: =Inputs!$E$83/Inputs!$E$100
B36: Z''-EM score | C36: x | D36: =Inputs!$D$259+Inputs!$D$260*$D$32+Inputs!$D$261*$D$33+Inputs!$D$262*$D$34+Inputs!$D$263*$D$35 | E36: =Inputs!$D$259+Inputs!$D$260*$E$32+Inputs!$D$261*$E$33+Inputs!$D$262*$E$34+Inputs!$D$263*$E$35
B37: Zone | D37: =IF($D$36>Inputs!$D$264,"Safe",IF($D$36>=Inputs!$D$265,"Grey","Distress")) | E37: =IF($E$36>Inputs!$D$264,"Safe",IF($E$36>=Inputs!$D$265,"Grey","Distress"))
B39: DuPont (FY2025; average balances)
D40: Value | G40: Notes
B41: Net margin | C41: % | D41: =Inputs!$E$49/Inputs!$E$23
B42: Asset turnover | C42: x | D42: =Inputs!$E$23/AVERAGE(Inputs!$D$75,Inputs!$E$75)
B43: Equity multiplier | C43: x | D43: =AVERAGE(Inputs!$D$75,Inputs!$E$75)/AVERAGE(Inputs!$D$83,Inputs!$E$83)
B44: ROE (3-step) | C44: % | D44: =$D$41*$D$42*$D$43
B45: Tax burden (net profit / PBT) | C45: x | D45: =Inputs!$E$49/Inputs!$E$45
...

Sheet Normalization
B2: MOPCO: Normalization
B3: Reported FY2025 operating profit to normalized EBIT and EBITDA. Each adjustment is an analyst assumption and can be switched off on Inputs.
B4: Blue = hardcoded input | Black = formula
B6: FY2025A
D7: Amount | E7: Include | F7: Removed | G7: Notes
B8: Reported operating profit | C8: EGP | D8: =Inputs!$E$36 | G8: Sourced fact
B9: Less: ECL reversal / (charge) | C9: EGP | D9: =Inputs!$E$34 | E9: =Inputs!$D$118 | F9: =$D$9*$E$9 | G9: Analyst assumption. Expected credit loss movements are non-recurring. Amount from the FY2025 income statement.
B10: Less: Provisions no longer required (inside other income) | C10: EGP | D10: =Inputs!$E$28 | E10: =Inputs!$D$119 | F10: =$D$10*$E$10 | G10: Analyst assumption. Release of prior-year provisions does not recur. Amount from the FY2025 income statement.
B11: Less: Capital gains / (losses) on disposals | C11: EGP | D11: =Inputs!$E$31 | E11: =Inputs!$D$120 | F11: =$D$11*$E$11 | G11: Analyst assumption. Disposal gains are not part of recurring operations. Amount from the FY2025 income statement.
B12: Total removed | C12: EGP | F12: =$F$9+$F$10+$F$11
B13: Normalized EBIT | C13: EGP | D13: =$D$8-$F$12
B14: Add: depreciation | C14: EGP | D14: =Inputs!$E$51 | G14: Sourced fact (notes)
B15: Add: amortization | C15: EGP | D15: =Inputs!$E$52 | G15: Sourced fact (notes)
B16: Normalized EBITDA | C16: EGP | D16: =$D$13+$D$14+$D$15
B17: Reported EBITDA (operating profit + D&A) | C17: EGP | D17: =$D$8+$D$14+$D$15
B19: Finance income and FX translation gains or losses are non-operating: excluded from FCFF; the related balance-sheet items enter the equity bridge.

Sheet Operating Model
B2: MOPCO: Operating model
B3: Revenue to EBITDA, EBIT, NOPAT, working capital, PP&E roll-forward, distributions and FCFF. Drivers from Inputs; base year from the audited statements.
B4: Blue = hardcoded input | Black = formula
B6: Operating model
C7: Unit | D7: 2025A | E7: 2026E | F7: 2027E | G7: 2028E | H7: 2029E | I7: 2030E | J7: Terminal | K7: Notes
B8: Revenue growth | C8: % | D8: =Inputs!$E$23/Inputs!$D$23-1 | E8: =Inputs!$D$182 | F8: =Inputs!$E$182 | G8: =Inputs!$F$182 | H8: =Inputs!$G$182 | I8: =Inputs!$H$182 | J8: =Inputs!$D$172 | K8: Inputs; terminal year = terminal growth
B9: Revenue | C9: EGP | D9: =Inputs!$E$23 | E9: =$D$9*(1+$E$8) | F9: =$E$9*(1+$F$8) | G9: =$F$9*(1+$G$8) | H9: =$G$9*(1+$H$8) | I9: =$H$9*(1+$I$8) | J9: =$I$9*(1+$J$8) | K9: Prior year × (1 + growth)
B10: Gross margin before D&A | C10: % | D10: =(Inputs!$E$26+Inputs!$E$51+Inputs!$E$52)/$D$9 | E10: =Inputs!$D$183 | F10: =Inputs!$E$183 | G10: =Inputs!$F$183 | H10: =Inputs!$G$183 | I10: =Inputs!$H$183 | J10: =Inputs!$I$183 | K10: All D&A assumed in cost of sales
B11: Gross profit before D&A | C11: EGP | D11: =$D$9*$D$10 | E11: =$E$9*$E$10 | F11: =$F$9*$F$10 | G11: =$G$9*$G$10 | H11: =$H$9*$H$10 | I11: =$I$9*$I$10 | J11: =$J$9*$J$10
B12: SG&A | C12: % revenue | D12: =-(Inputs!$E$29+Inputs!$E$30)/$D$9 | E12: =Inputs!$D$184 | F12: =Inputs!$E$184 | G12: =Inputs!$F$184 | H12: =Inputs!$G$184 | I12: =Inputs!$H$184 | J12: =Inputs!$I$184
B13: SG&A | C13: EGP | D13: =-(Inputs!$E$29+Inputs!$E$30) | E13: =$E$9*$E$12 | F13: =$F$9*$F$12 | G13: =$G$9*$G$12 | H13: =$H$9*$H$12 | I13: =$I$9*$I$12 | J13: =$J$9*$J$12
B14: Other operating (net) | C14: % revenue | D14: =(Normalization!$D$13-Inputs!$E$26-Inputs!$E$29-Inputs!$E$30)/$D$9 | E14: =Inputs!$D$185 | F14: =Inputs!$E$185 | G14: =Inputs!$F$185 | H14: =Inputs!$G$185 | I14: =Inputs!$H$185 | J14: =Inputs!$I$185 | K14: Normalized: after removing non-recurring items
B15: Other operating income (net) | C15: EGP | D15: =Normalization!$D$13-Inputs!$E$26-Inputs!$E$29-Inputs!$E$30 | E15: =$E$9*$E$14 | F15: =$F$9*$F$14 | G15: =$G$9*$G$14 | H15: =$H$9*$H$14 | I15: =$I$9*$I$14 | J15: =$J$9*$J$14
B16: EBITDA | C16: EGP | D16: =$D$11-$D$13+$D$15 | E16: =$E$11-$E$13+$E$15 | F16: =$F$11-$F$13+$F$15 | G16: =$G$11-$G$13+$G$15 | H16: =$H$11-$H$13+$H$15 | I16: =$I$11-$I$13+$I$15 | J16: =$J$11-$J$13+$J$15 | K16: Base year = normalized EBITDA
B17: Opening PP&E | C17: EGP | E17: =Inputs!$E$57 | F17: =$E$22 | G17: =$F$22 | H17: =$G$22 | I17: =$H$22 | J17: =$I$22
B18: Depreciation | C18: EGP | D18: =Inputs!$E$51 | E18: =IF(Inputs!$D$180="ppe_rollforward",Inputs!$D$187*$E$17,$E$9*Inputs!$D$186) | F18: =IF(Inputs!$D$180="ppe_rollforward",Inputs!$E$187*$F$17,$F$9*Inputs!$E$186) | G18: =IF(Inputs!$D$180="ppe_rollforward",Inputs!$F$187*$G$17,$G$9*Inputs!$F$186) | H18: =IF(Inputs!$D$180="ppe_rollforward",Inputs!$G$187*$H$17,$H$9*Inputs!$G$186) | I18: =IF(Inputs!$D$180="ppe_rollforward",Inputs!$H$187*$I$17,$I$9*Inputs!$H$186) | J18: =IF(Inputs!$D$180="ppe_rollforward",Inputs!$I$187*$J$17,$J$9*Inputs!$I$186) | K18: Roll-forward: rate × opening PP&E; % revenue mode: D&A % × revenue
B19: Amortization | C19: EGP | D19: =Inputs!$E$52 | E19: =IF(Inputs!$D$180="ppe_rollforward",$E$9*Inputs!$D$188,0) | F19: =IF(Inputs!$D$180="ppe_rollforward",$F$9*Inputs!$E$188,0) | G19: =IF(Inputs!$D$180="ppe_rollforward",$G$9*Inputs!$F$188,0) | H19: =IF(Inputs!$D$180="ppe_rollforward",$H$9*Inputs!$G$188,0) | I19: =IF(Inputs!$D$180="ppe_rollforward",$I$9*Inputs!$H$188,0) | J19: =IF(Inputs!$D$180="ppe_rollforward",$J$9*Inputs!$I$188,0)
B20: D&A | C20: EGP | D20: =$D$18+$D$19 | E20: =$E$18+$E$19 | F20: =$F$18+$F$19 | G20: =$G$18+$G$19 | H20: =$H$18+$H$19 | I20: =$I$18+$I$19 | J20: =$J$18+$J$19
B21: Capex | C21: EGP | D21: =-Inputs!$E$111 | E21: =IF(Inputs!$D$181="absolute",Inputs!$D$190,$E$9*Inputs!$D$189) | F21: =IF(Inputs!$D$181="absolute",Inputs!$E$190,$F$9*Inputs!$E$189) | G21: =IF(Inputs!$D$181="absolute",Inputs!$F$190,$G$9*Inputs!$F$189) | H21: =IF(Inputs!$D$181="absolute",Inputs!$G$190,$H$9*Inputs!$G$189) | I21: =IF(Inputs!$D$181="absolute",Inputs!$H$190,$I$9*Inputs!$H$189) | J21: =$J$9*Inputs!$I$189 | K21: Terminal year: % revenue (value-driver consistent)
B22: Closing PP&E | C22: EGP | D22: =Inputs!$E$57 | E22: =$E$17+$E$21-$E$18 | F22: =$F$17+$F$21-$F$18 | G22: =$G$17+$G$21-$G$18 | H22: =$H$17+$H$21-$H$18 | I22: =$I$17+$I$21-$I$18 | J22: =$J$17+$J$21-$J$18 | K22: Opening + capex − depreciation
B23: EBIT | C23: EGP | D23: =$D$16-$D$20 | E23: =$E$16-$E$20 | F23: =$F$16-$F$20 | G23: =$G$16-$G$20 | H23: =$H$16-$H$20 | I23: =$I$16-$I$20 | J23: =$J$16-$J$20 | K23: Base year = normalized EBIT
B24: Tax rate on EBIT | C24: % | D24: =Inputs!$D$133 | E24: =Inputs!$D$196 | F24: =Inputs!$E$196 | G24: =Inputs!$F$196 | H24: =Inputs!$G$196 | I24: =Inputs!$H$196 | J24: =Inputs!$I$196
B25: Tax on EBIT | C25: EGP | D25: =$D$23*$D$24 | E25: =$E$23*$E$24 | F25: =$F$23*$F$24 | G25: =$G$23*$G$24 | H25: =$H$23*$H$24 | I25: =$I$23*$I$24 | J25: =$J$23*$J$24
B26: NOPAT | C26: EGP | D26: =$D$23-$D$25 | E26: =$E$23-$E$25 | F26: =$F$23-$F$25 | G26: =$G$23-$G$25 | H26: =$H$23-$H$25 | I26: =$I$23-$I$25 | J26: =$J$23-$J$25
B27: Cash cost of sales | C27: EGP | D27: =$D$9*(1-$D$10) | E27: =$E$9*(1-$E$10) | F27: =$F$9*(1-$F$10) | G27: =$G$9*(1-$G$10) | H27: =$H$9*(1-$H$10) | I27: =$I$9*(1-$I$10) | J27: =$J$9*(1-$J$10) | K27: Revenue × (1 − gross margin before D&A)
B28: Receivable days | C28: days | D28: =Inputs!$E$67/$D$9*Inputs!$D$18 | E28: =Inputs!$D$191 | F28: =Inputs!$E$191 | G28: =Inputs!$F$191 | H28: =Inputs!$G$191 | I28: =Inputs!$H$191 | J28: =Inputs!$I$191
B29: Accounts receivable | C29: EGP | D29: =Inputs!$E$67 | E29: =$E$9*$E$28/Inputs!$D$18 | F29: =$F$9*$F$28/Inputs!$D$18 | G29: =$G$9*$G$28/Inputs!$D$18 | H29: =$H$9*$H$28/Inputs!$D$18 | I29: =$I$9*$I$28/Inputs!$D$18 | J29: =$J$9*$J$28/Inputs!$D$18
B30: Inventory days | C30: days | D30: =Inputs!$E$66/$D$27*Inputs!$D$18 | E30: =Inputs!$D$192 | F30: =Inputs!$E$192 | G30: =Inputs!$F$192 | H30: =Inputs!$G$192 | I30: =Inputs!$H$192 | J30: =Inputs!$I$192
B31: Inventory | C31: EGP | D31: =Inputs!$E$66 | E31: =$E$27*$E$30/Inputs!$D$18 | F31: =$F$27*$F$30/Inputs!$D$18 | G31: =$G$27*$G$30/Inputs!$D$18 | H31: =$H$27*$H$30/Inputs!$D$18 | I31: =$I$27*$I$30/Inputs!$D$18 | J31: =$J$27*$J$30/Inputs!$D$18
B32: Payable days | C32: days | D32: =Inputs!$E$93/$D$27*Inputs!$D$18 | E32: =Inputs!$D$193 | F32: =Inputs!$E$193 | G32: =Inputs!$F$193 | H32: =Inputs!$G$193 | I32: =Inputs!$H$193 | J32: =Inputs!$I$193
B33: Trade payables | C33: EGP | D33: =Inputs!$E$93 | E33: =$E$27*$E$32/Inputs!$D$18 | F33: =$F$27*$F$32/Inputs!$D$18 | G33: =$G$27*$G$32/Inputs!$D$18 | H33: =$H$27*$H$32/Inputs!$D$18 | I33: =$I$27*$I$32/Inputs!$D$18 | J33: =$J$27*$J$32/Inputs!$D$18
B34: Other operating current assets | C34: % revenue | D34: =(Inputs!$E$70+Inputs!$E$72+Inputs!$E$71)/$D$9 | E34: =Inputs!$D$194 | F34: =Inputs!$E$194 | G34: =Inputs!$F$194 | H34: =Inputs!$G$194 | I34: =Inputs!$H$194 | J34: =Inputs!$I$194
B35: Other operating current assets | C35: EGP | D35: =Inputs!$E$70+Inputs!$E$72+Inputs!$E$71 | E35: =$E$9*$E$34 | F35: =$F$9*$F$34 | G35: =$G$9*$G$34 | H35: =$H$9*$H$34 | I35: =$I$9*$I$34 | J35: =$J$9*$J$34 | K35: Debtors and other debit balances, supplier advances, due from related parties
B36: Other operating current liabilities | C36: % revenue | D36: =(Inputs!$E$94+Inputs!$E$95+Inputs!$E$97+Inputs!$E$98+Inputs!$E$99)/$D$9 | E36: =Inputs!$D$195 | F36: =Inputs!$E$195 | G36: =Inputs!$F$195 | H36: =Inputs!$G$195 | I36: =Inputs!$H$195 | J36: =Inputs!$I$195
B37: Other operating current liabilities | C37: EGP | D37: =Inputs!$E$94+Inputs!$E$95+Inputs!$E$97+Inputs!$E$98+Inputs!$E$99 | E37: =$E$9*$E$36 | F37: =$F$9*$F$36 | G37: =$G$9*$G$36 | H37: =$H$9*$H$36 | I37: =$I$9*$I$36 | J37: =$J$9*$J$36 | K37: Creditors and other credit balances, customer advances, provisions, due to related parties
B38: Operating net working capital | C38: EGP | D38: =$D$29+$D$31+$D$35-$D$33-$D$37 | E38: =$E$29+$E$31+$E$35-$E$33-$E$37 | F38: =$F$29+$F$31+$F$35-$F$33-$F$37 | G38: =$G$29+$G$31+$G$35-$G$33-$G$37 | H38: =$H$29+$H$31+$H$35-$H$33-$H$37 | I38: =$I$29+$I$31+$I$35-$I$33-$I$37 | J38: =$J$29+$J$31+$J$35-$J$33-$J$37
B39: Change in net working capital | C39: EGP | E39: =$E$38-$D$38 | F39: =$F$38-$E$38 | G39: =$G$38-$F$38 | H39: =$H$38-$G$38 | I39: =$I$38-$H$38 | J39: =$J$38-$I$38
B40: Net profit (forecast: NOPAT + after-tax net finance income) | C40: EGP | D40: =Inputs!$E$49 | E40: =$E$26+Inputs!$D$202*(1-$E$24) | F40: =$F$26+Inputs!$D$202*(1-$F$24) | G40: =$G$26+Inputs!$D$202*(1-$G$24) | H40: =$H$26+Inputs!$D$202*(1-$H$24) | I40: =$I$26+Inputs!$D$202*(1-$I$24) | J40: =$J$26+Inputs!$D$202*(1-$J$24) | K40: Distribution base and forward P/E only
B41: Employee and board distributions | C41: EGP | E41: =IF(Inputs!$D$200=1,Inputs!$D$201*$D$40,0) | F41: =IF(Inputs!$D$200=1,Inputs!$D$201*$E$40,0) | G41: =IF(Inputs!$D$200=1,Inputs!$D$201*$F$40,0) | H41: =IF(Inputs!$D$200=1,Inputs!$D$201*$G$40,0) | I41: =IF(Inputs!$D$200=1,Inputs!$D$201*$H$40,0) | J41: =IF(Inputs!$D$200=1,Inputs!$D$201*$I$40,0) | K41: % of prior-year net profit
B42: Free cash flow to the firm (FCFF) | C42: EGP | E42: =$E$26+$E$20-$E$21-$E$39-$E$41 | F42: =$F$26+$F$20-$F$21-$F$39-$F$41 | G42: =$G$26+$G$20-$G$21-$G$39-$G$41 | H42: =$H$26+$H$20-$H$21-$H$39-$H$41 | I42: =$I$26+$I$20-$I$21-$I$39-$I$41 | J42: =$J$26+$J$20-$J$21-$J$39-$J$41 | K42: NOPAT + D&A − capex − change in NWC − distributions

Sheet WACC
B2: MOPCO: Cost of capital
B3: Risk-free rate, bottom-up beta, cost of equity, cost of debt and weights. All rates from the frozen snapshot on Inputs.
B4: Blue = hardcoded input | Black = formula
B6: Risk-free rate
D7: Value | E7: Notes
B8: (a) EGP 10Y secondary YTM | C8: % | D8: =Inputs!$D$124 | E8: As of 2026-05-21, status stale
B9: (b) CBE auction yield (selected tenor) | C9: % | D9: =Inputs!$D$159
B10: (c) Damodaran inflation-based EGP riskfree | C10: % | D10: =Inputs!$D$126
B11: (d) US 10Y converted with expected inflation (Fisher) | C11: % | D11: =(1+Inputs!$D$127)*(1+Inputs!$D$128)/(1+Inputs!$D$129)-1
B12: Risk-free rate used | C12: % | D12: =IF(Inputs!$D$158="eg_10y_secondary",$D$8,IF(Inputs!$D$158="cbe_auction",$D$9,IF(Inputs!$D$158="damodaran_egp",$D$10,$D$11))) | E12: Source: eg_10y_secondary
B13: Clean risk-free rate (1 = yes) | C13: flag | D13: =IF(OR(Inputs!$D$158="damodaran_egp",Inputs!$D$158="fisher_us10y"),1,0) | E13: Local government yields already contain sovereign default risk
B15: Beta (bottom-up)
D16: Value | E16: Notes
B17: Unlevered beta (corrected for cash) | C17: x | D17: =Inputs!$D$136 | E17: Industry: Chemical (Basic); dataset 2026-01-05
B18: Interest-bearing debt (bank, bonds, leases) | C18: EGP | D18: =Inputs!$E$90+Inputs!$E$84+Inputs!$E$85+Inputs!$E$91+Inputs!$E$86 | E18: Book value as market-value proxy
B19: Market value of equity | C19: EGP | D19: =Inputs!$D$11*Inputs!$D$15 | E19: Price × diluted shares
B20: D/E | C20: x | D20: =$D$18/$D$19
B21: Levered beta | C21: x | D21: =$D$17*(1+(1-Inputs!$D$163)*$D$20) | E21: βU × (1 + (1 − t) × D/E)
B23: Cost of equity
D24: Value | E24: Notes
B25: Mature-market ERP | C25: % | D25: =Inputs!$D$130
B26: Egypt country risk premium | C26: % | D26: =Inputs!$D$131
B27: Size / illiquidity premium | C27: % | D27: =Inputs!$D$162
B28: Premium multiplied by beta | C28: % | D28: =IF(Inputs!$D$160="B",$D$25+$D$26,$D$25) | E28: Method B loads CRP into the beta premium
B29: Premium added outside beta | C29: % | D29: =IF(Inputs!$D$160="A",$D$26,IF(Inputs!$D$160="C",Inputs!$D$161*$D$26,0))+$D$27 | E29: Method A: CRP; C: λ × CRP; local_rf and B: none
B30: Cost of equity (Ke) | C30: % | D30: =$D$12+$D$21*$D$28+$D$29 | E30: Method local_rf
B32: Cost of debt
D33: Value | E33: Notes
B34: Debt and lease interest (employee-benefit interest excluded) | C34: EGP | D34: =-(Inputs!$E$38+Inputs!$E$39)
B35: Interest coverage (normalized EBIT / interest) | C35: x | D35: =IF($D$34>0,Normalization!$D$13/$D$34,"no interest")
B36: Synthetic rating table row | C36: row | D36: =IF($D$34>0,MATCH($D$35,Inputs!$D$140:$D$154,1),ROWS(Inputs!$D$140:$D$154)) | E36: Largest lower coverage bound not above the coverage
B37: Synthetic rating | C37: text | D37: =INDEX(Inputs!$E$140:$E$154,$D$36)
B38: Company default spread | C38: % | D38: =INDEX(Inputs!$F$140:$F$154,$D$36)
B39: Country default spread (added when Rf is clean) | C39: % | D39: =Inputs!$D$132
B40: Kd, synthetic | C40: % | D40: =$D$12+$D$38+$D$13*$D$39
B41: Kd, CBE lending + spread | C41: % | D41: =Inputs!$D$135+Inputs!$D$165
B42: Kd, actual (interest / average interest-bearing debt) | C42: % | D42: =IFERROR($D$34/(AVERAGE($D$18,Inputs!$D$90+Inputs!$D$84+Inputs!$D$85+Inputs!$D$91+Inputs!$D$86)),"n/a")
B43: Pre-tax cost of debt used | C43: % | D43: =IF(Inputs!$D$164="synthetic",$D$40,IF(Inputs!$D$164="cbe_plus_spread",$D$41,$D$42)) | E43: Method synthetic
B44: Tax rate | C44: % | D44: =Inputs!$D$133
B45: After-tax cost of debt | C45: % | D45: =$D$43*(1-$D$44)
...

Sheet DCF
B2: MOPCO: DCF
B3: Stub year and mid-year timing from the valuation date; Gordon and exit-multiple terminal values; equity bridge from the latest balance sheet (cash flows between the year end and the valuation date are not captured).
B4: Blue = hardcoded input | Black = formula
B6: Discounting (valuation date, stub, mid-year)
C7: Unit | D7: 2026E | E7: 2027E | F7: 2028E | G7: 2029E | H7: 2030E | I7: Notes
B8: Fiscal year ended | C8: date | D8: =DATE(YEAR(Inputs!$D$16)+1,MONTH(Inputs!$D$16),DAY(Inputs!$D$16)) | E8: =DATE(YEAR($D$8)+1,MONTH($D$8),DAY($D$8)) | F8: =DATE(YEAR($E$8)+1,MONTH($E$8),DAY($E$8)) | G8: =DATE(YEAR($F$8)+1,MONTH($F$8),DAY($F$8)) | H8: =DATE(YEAR($G$8)+1,MONTH($G$8),DAY($G$8))
B9: Period start | C9: date | D9: =MAX(Inputs!$D$10,Inputs!$D$16) | E9: =$D$8 | F9: =$E$8 | G9: =$F$8 | H9: =$G$8
B10: Share of year cash flow included | C10: % | D10: =IF(Inputs!$D$10>Inputs!$D$16,YEARFRAC(Inputs!$D$10,$D$8,1),1) | E10: =YEARFRAC($E$9,$E$8,1) | F10: =YEARFRAC($F$9,$F$8,1) | G10: =YEARFRAC($G$9,$G$8,1) | H10: =YEARFRAC($H$9,$H$8,1) | I10: Year 1 = YEARFRAC(valuation date, first fiscal year end, actual/actual)
B11: Date for discounting | C11: date | D11: =IF(Inputs!$D$17=1,AVERAGE($D$9,$D$8),$D$8) | E11: =IF(Inputs!$D$17=1,AVERAGE($E$9,$E$8),$E$8) | F11: =IF(Inputs!$D$17=1,AVERAGE($F$9,$F$8),$F$8) | G11: =IF(Inputs!$D$17=1,AVERAGE($G$9,$G$8),$G$8) | H11: =IF(Inputs!$D$17=1,AVERAGE($H$9,$H$8),$H$8) | I11: Mid-point of the period when mid-year is on, else period end
B12: Years from valuation date | C12: years | D12: =($D$11-Inputs!$D$10)/Inputs!$D$18 | E12: =($E$11-Inputs!$D$10)/Inputs!$D$18 | F12: =($F$11-Inputs!$D$10)/Inputs!$D$18 | G12: =($G$11-Inputs!$D$10)/Inputs!$D$18 | H12: =($H$11-Inputs!$D$10)/Inputs!$D$18
B13: Discount factor | C13: x | D13: =(1+WACC!$D$54)^(-$D$12) | E13: =(1+WACC!$D$54)^(-$E$12) | F13: =(1+WACC!$D$54)^(-$F$12) | G13: =(1+WACC!$D$54)^(-$G$12) | H13: =(1+WACC!$D$54)^(-$H$12)
B14: FCFF | C14: EGP | D14: ='Operating Model'!$E$42 | E14: ='Operating Model'!$F$42 | F14: ='Operating Model'!$G$42 | G14: ='Operating Model'!$H$42 | H14: ='Operating Model'!$I$42 | I14: Operating Model
B15: FCFF included | C15: EGP | D15: =$D$14*$D$10 | E15: =$E$14*$E$10 | F15: =$F$14*$F$10 | G15: =$G$14*$G$10 | H15: =$H$14*$H$10
B16: Present value | C16: EGP | D16: =$D$15*$D$13 | E16: =$E$15*$E$13 | F16: =$F$15*$F$13 | G16: =$G$15*$G$13 | H16: =$H$15*$H$13
B18: Terminal value
D19: Value | I19: Notes
B20: Sum of present values | C20: EGP | D20: =SUM($D$16:$H$16)
B21: Years to final period end | C21: years | D21: =($H$8-Inputs!$D$10)/Inputs!$D$18 | I21: Terminal value discounted from the final period end
B22: Terminal discount factor | C22: x | D22: =(1+WACC!$D$54)^(-$D$21)
B23: Terminal-year FCFF | C23: EGP | D23: ='Operating Model'!$J$42
B24: Gordon terminal value | C24: EGP | D24: =IF(Inputs!$D$172<WACC!$D$54,$D$23/(WACC!$D$54-Inputs!$D$172),"n/a: g ≥ WACC") | I24: FCFF(n+1) / (WACC − g)
B25: PV of Gordon terminal value | C25: EGP | D25: =IFERROR($D$24*$D$22,"n/a")
B26: Final-year EBITDA | C26: EGP | D26: ='Operating Model'!$I$16
B27: Exit-multiple terminal value | C27: EGP | D27: =$D$26*Inputs!$D$173 | I27: EBITDA(n) × exit multiple
B28: PV of exit-multiple terminal value | C28: EGP | D28: =$D$27*$D$22
B29: PV of terminal value used | C29: EGP | D29: =IF(Inputs!$D$171="gordon",$D$25,$D$28) | I29: Method: gordon
B30: Enterprise value | C30: EGP | D30: =$D$20+$D$29
B31: PV of terminal value / EV | C31: % | D31: =$D$29/$D$30
B32: Implied exit multiple from Gordon | C32: x | D32: =IFERROR($D$24/$D$26,"n/a")
B33: Implied growth from exit value | C33: % | D33: =WACC!$D$54-$D$23/$D$27 | I33: WACC − FCFF(n+1) / exit TV
B34: RONIC | C34: % | D34: =IF(ISNUMBER(Inputs!$D$175),Inputs!$D$175,WACC!$D$54)
B35: Reinvestment rate implied by g / RONIC | C35: % | D35: =Inputs!$D$172/$D$34
B36: Terminal-year reinvestment rate in the forecast | C36: % | D36: =('Operating Model'!$J$21-'Operating Model'!$J$20+'Operating Model'!$J$39)/'Operating Model'!$J$26 | I36: (Capex − D&A + change in NWC) / NOPAT
B38: Enterprise value to equity value (balance sheet 2025-12-31)
D39: Value | I39: Notes
B40: Add: cash and cash equivalents | C40: EGP | D40: =Inputs!$E$74 | I40: Balance sheet
B41: Add: FVTPL securities | C41: EGP | D41: =Inputs!$E$69 | I41: Balance sheet
B42: Add: amortized-cost investments (current) | C42: EGP | D42: =Inputs!$E$68 | I42: Balance sheet
B43: Add: amortized-cost investments (non-current) | C43: EGP | D43: =Inputs!$E$62 | I43: Balance sheet
B44: Add: associates | C44: EGP | D44: =IF(ISNUMBER(Inputs!$D$205),Inputs!$D$205,Inputs!$E$61) | I44: Balance sheet
...

Sheet USD Check
B2: MOPCO: USD consistency check
B3: EGP cash flows converted at inflation-parity forward rates and discounted at a USD cost of capital. A consistency check of the EGP discount rate, not a second answer.
B4: Blue = hardcoded input | Black = formula
B6: Forward exchange rates
C7: Unit | D7: 2026E | E7: 2027E | F7: 2028E | G7: 2029E | H7: 2030E | I7: Notes
B8: EGP inflation | C8: % | D8: =Inputs!$D$225 | E8: =Inputs!$E$225 | F8: =Inputs!$F$225 | G8: =Inputs!$G$225 | H8: =Inputs!$H$225
B9: USD inflation | C9: % | D9: =Inputs!$D$226 | E9: =Inputs!$E$226 | F9: =Inputs!$F$226 | G9: =Inputs!$G$226 | H9: =Inputs!$H$226
B10: Inflation differential | C10: % | D10: =(1+$D$8)/(1+$D$9)-1 | E10: =(1+$E$8)/(1+$E$9)-1 | F10: =(1+$F$8)/(1+$F$9)-1 | G10: =(1+$G$8)/(1+$G$9)-1 | H10: =(1+$H$8)/(1+$H$9)-1
B11: Forward USD/EGP | C11: EGP/USD | D11: =Inputs!$D$134*(1+$D$8)/(1+$D$9) | E11: =$D$11*(1+$E$8)/(1+$E$9) | F11: =$E$11*(1+$F$8)/(1+$F$9) | G11: =$F$11*(1+$G$8)/(1+$G$9) | H11: =$G$11*(1+$H$8)/(1+$H$9) | I11: S0 × Π (1 + π EGP) / (1 + π USD)
B12: FCFF included, USD | C12: USD | D12: =DCF!$D$10*'Operating Model'!$E$42/$D$11 | E12: =DCF!$E$10*'Operating Model'!$F$42/$E$11 | F12: =DCF!$F$10*'Operating Model'!$G$42/$F$11 | G12: =DCF!$G$10*'Operating Model'!$H$42/$G$11 | H12: =DCF!$H$10*'Operating Model'!$I$42/$H$11
B14: USD cost of capital (method A in USD)
D15: Value | I15: Notes
B16: US 10Y Treasury | C16: % | D16: =Inputs!$D$127
B17: Cost of equity, USD | C17: % | D17: =$D$16+WACC!$D$21*WACC!$D$25+WACC!$D$26+WACC!$D$27 | I17: US 10Y + βL × ERP + CRP + size premium
B18: Cost of debt, USD (pre-tax) | C18: % | D18: =$D$16+WACC!$D$46+WACC!$D$39 | I18: US 10Y + company spread + country default spread
B19: WACC, USD | C19: % | D19: =WACC!$D$52*$D$17+WACC!$D$53*$D$18*(1-WACC!$D$44)
B21: USD valuation
C22: Unit | D22: 2026E | E22: 2027E | F22: 2028E | G22: 2029E | H22: 2030E | I22: Notes
B23: Discount factor, USD | C23: x | D23: =(1+$D$19)^(-DCF!$D$12) | E23: =(1+$D$19)^(-DCF!$E$12) | F23: =(1+$D$19)^(-DCF!$F$12) | G23: =(1+$D$19)^(-DCF!$G$12) | H23: =(1+$D$19)^(-DCF!$H$12)
B24: Present value, USD | C24: USD | D24: =$D$12*$D$23 | E24: =$E$12*$E$23 | F24: =$F$12*$F$23 | G24: =$G$12*$G$23 | H24: =$H$12*$H$23
B26: USD bridge and comparison
D27: Value | I27: Notes
B28: Forward USD/EGP, terminal year | C28: EGP/USD | D28: =$H$11*(1+$H$8)/(1+$H$9)
B29: Terminal growth, USD | C29: % | D29: =(1+Inputs!$D$172)*(1+$H$9)/(1+$H$8)-1 | I29: Same real growth as the EGP terminal growth
B30: Sum of present values, USD | C30: USD | D30: =SUM($D$24:$H$24)
B31: Terminal value, USD | C31: USD | D31: =IF(Inputs!$D$171="gordon",'Operating Model'!$J$42/$D$28/($D$19-$D$29),'Operating Model'!$I$16/$H$11*Inputs!$D$173)
B32: PV of terminal value, USD | C32: USD | D32: =$D$31*(1+$D$19)^(-DCF!$D$21)
B33: Enterprise value, USD | C33: USD | D33: =$D$30+$D$32
B34: Bridge, USD (EGP bridge / spot) | C34: USD | D34: =DCF!$D$51/Inputs!$D$134
B35: Equity value, USD | C35: USD | D35: =$D$33+$D$34
B36: USD equity value converted at spot | C36: EGP | D36: =$D$35*Inputs!$D$134
B37: Equity value, EGP DCF | C37: EGP | D37: =DCF!$D$52
B38: Gap (USD-derived / EGP - 1) | C38: % | D38: =$D$36/$D$37-1
B39: Risk-free differential (EGP Rf - US 10Y) | C39: pp | D39: =WACC!$D$12-$D$16
B40: Average inflation differential | C40: pp | D40: =AVERAGE($D$10:$H$10)
B42: =IF(ABS($D$38)<=Inputs!$D$255,"The USD valuation converted at spot is within "&TEXT(ABS($D$38),"0.0%")&" of the EGP valuation. The EGP discount rate and the inflation path used for forward FX rates are broadly consistent.","The USD valuation converted at spot is "&TEXT(ABS($D$38),"0.0%")&IF($D$38>0," above"," below")&" the EGP valuation. The EGP risk-free rate exceeds the US 10Y by "&SUBSTITUTE(TEXT($D$39,"0.00%"),"%","pp")&", while the forward FX rates assume an average inflation differential of "&SUBSTITUTE(TEXT($D$40,"0.00%"),"%","pp")&"; the EGP discount rate implies "&IF($D$38>0,"more","less")&" depreciation than the inflation path.")

Sheet DDM
B2: MOPCO: Dividend discount model
B3: Shareholder dividends only (employee and board distributions excluded). Two-stage model (headline) and H-model, discounted at the cost of equity.
B4: Blue = hardcoded input | Black = formula
B6: Inputs
D7: Value | I7: Notes
B8: DPS (base year) | C8: EGP | D8: =IF(ISNUMBER(Inputs!$D$217),Inputs!$D$217,-Inputs!$E$112/Inputs!$D$13) | I8: FY2025 dividends paid to shareholders / basic shares
B9: Cost of equity | C9: % | D9: =WACC!$D$30
B10: High-growth rate | C10: % | D10: =Inputs!$D$218
B11: Stable growth | C11: % | D11: =Inputs!$D$220
B12: High-growth years | C12: years | D12: =Inputs!$D$219 | I12: Columns below are laid out for this number of years
B14: Dividends
D15: Year 1 | E15: Year 2 | F15: Year 3 | G15: Year 4 | H15: Year 5 | I15: Notes
B16: Dividend per share | C16: EGP | D16: =$D$8*(1+$D$10) | E16: =$D$16*(1+$D$10) | F16: =$E$16*(1+$D$10) | G16: =$F$16*(1+$D$10) | H16: =$G$16*(1+$D$10)
B17: Discount factor | C17: x | D17: =1/(1+$D$9) | E17: =$D$17/(1+$D$9) | F17: =$E$17/(1+$D$9) | G17: =$F$17/(1+$D$9) | H17: =$G$17/(1+$D$9)
B18: Present value | C18: EGP | D18: =$D$16*$D$17 | E18: =$E$16*$E$17 | F18: =$F$16*$F$17 | G18: =$G$16*$G$17 | H18: =$H$16*$H$17
B20: Value per share
D21: Value | I21: Notes
B22: PV of high-growth dividends | C22: EGP | D22: =SUM($D$18:$H$18)
B23: Terminal value at end of high growth | C23: EGP | D23: =IF($D$9>$D$11,$H$16*(1+$D$11)/($D$9-$D$11),"n/a: Ke ≤ g")
B24: PV of terminal value | C24: EGP | D24: =IFERROR($D$23*$H$17,"n/a")
B25: Two-stage value per share | C25: EGP | D25: =IFERROR($D$22+$D$24,"n/a")
B26: H (half-life of high growth) | C26: years | D26: =$D$12*Inputs!$D$221
B27: H-model value per share | C27: EGP | D27: =IF($D$9>$D$11,$D$8*(1+$D$11)/($D$9-$D$11)+$D$8*$D$26*($D$10-$D$11)/($D$9-$D$11),"n/a")
B29: Sustainability
D30: Value | I30: Notes
B31: ROE (net profit / average equity) | C31: % | D31: =Inputs!$E$49/AVERAGE(Inputs!$D$83,Inputs!$E$83)
B32: Payout (shareholder dividends / net profit) | C32: % | D32: =-Inputs!$E$112/Inputs!$E$49
B33: Sustainable growth (ROE × retention) | C33: % | D33: =$D$31*(1-$D$32)
B34: Stable growth within sustainable growth | C34: check | D34: =$D$11<=$D$33 | I34: FALSE = warning: stable growth exceeds ROE × retention
B35: Payout at or below 100% | C35: check | D35: =$D$32<=1

Sheet Comps Precedents SOTP
B2: MOPCO: Comparables, precedents and SOTP
B3: Multiples computed from the raw peer and transaction inputs on Inputs; implied values use the equity bridge of the DCF sheet. Methods without inputs are excluded from the blend.
B4: Blue = hardcoded input | Black = formula
B6: Trading comparables
B7: No peers entered on Inputs. No multiple is computed and the method is excluded from the blend.
B9: Precedent transactions
B10: No transactions entered on Inputs. The method is excluded from the blend.
B12: Sum of the parts
B13: No segments entered on Inputs. The method is excluded from the blend.
B15: Broker targets (reference only)
B16: No broker targets entered.

Sheet Scenarios
B2: MOPCO: Scenarios
B3: Bear, Base and Bull are explicit driver sets on Inputs; each is a full re-run of the operating model and DCF below. Probabilities must sum to 100%.
B4: Blue = hardcoded input | Black = formula
B6: Scenario summary
D7: Bear | E7: Base | F7: Bull | K7: Notes
B8: Probability | C8: % | D8: =Inputs!$D$209 | E8: =Inputs!$E$209 | F8: =Inputs!$F$209
B9: Revenue growth delta (every year) | C9: pp | D9: =Inputs!$D$210 | E9: =Inputs!$E$210 | F9: =Inputs!$F$210
B10: Gross margin delta | C10: pp | D10: =Inputs!$D$211 | E10: =Inputs!$E$211 | F10: =Inputs!$F$211
B11: WACC delta | C11: pp | D11: =Inputs!$D$212 | E11: =Inputs!$E$212 | F11: =Inputs!$F$212
B12: Terminal growth delta | C12: pp | D12: =Inputs!$D$213 | E12: =Inputs!$E$213 | F12: =Inputs!$F$213
B13: WACC used | C13: % | D13: =Scenarios!$D$27 | E13: =Scenarios!$D$64 | F13: =Scenarios!$D$101
B14: Terminal growth used | C14: % | D14: =Scenarios!$D$28 | E14: =Scenarios!$D$65 | F14: =Scenarios!$D$102
B15: Enterprise value | C15: EGP | D15: =Scenarios!$D$58 | E15: =Scenarios!$D$95 | F15: =Scenarios!$D$132
B16: Equity value | C16: EGP | D16: =Scenarios!$D$59 | E16: =Scenarios!$D$96 | F16: =Scenarios!$D$133
B17: Value per share | C17: EGP | D17: =Scenarios!$D$60 | E17: =Scenarios!$D$97 | F17: =Scenarios!$D$134
B18: Upside versus price | C18: % | D18: =IFERROR(Scenarios!$D$60/Inputs!$D$11-1,"n/a") | E18: =IFERROR(Scenarios!$D$97/Inputs!$D$11-1,"n/a") | F18: =IFERROR(Scenarios!$D$134/Inputs!$D$11-1,"n/a")
B19: Probability sum | C19: % | D19: =SUM($D$8:$F$8)
B20: Probability-weighted value per share | C20: EGP | D20: =SUMPRODUCT($D$8:$F$8,$D$17:$F$17)
B25: Bear case: operating model and DCF
C26: Unit | D26: 2025A | E26: 2026E | F26: 2027E | G26: 2028E | H26: 2029E | I26: 2030E | J26: Terminal | K26: Notes
B27: Bear: WACC used | C27: % | D27: =WACC!$D$54+Inputs!$D$212
B28: Bear: terminal growth used | C28: % | D28: =Inputs!$D$172+Inputs!$D$213
B29: Bear: Revenue | C29: EGP | D29: =Inputs!$E$23 | E29: =$D$29*(1+(Inputs!$D$182+Inputs!$D$210)) | F29: =$E$29*(1+(Inputs!$E$182+Inputs!$D$210)) | G29: =$F$29*(1+(Inputs!$F$182+Inputs!$D$210)) | H29: =$G$29*(1+(Inputs!$G$182+Inputs!$D$210)) | I29: =$H$29*(1+(Inputs!$H$182+Inputs!$D$210)) | J29: =$I$29*(1+(Inputs!$D$172+Inputs!$D$213))
B30: Bear: Gross profit before D&A | C30: EGP | D30: =$D$29*((Inputs!$E$26+Inputs!$E$51+Inputs!$E$52)/$D$29) | E30: =$E$29*(Inputs!$D$183+Inputs!$D$211) | F30: =$F$29*(Inputs!$E$183+Inputs!$D$211) | G30: =$G$29*(Inputs!$F$183+Inputs!$D$211) | H30: =$H$29*(Inputs!$G$183+Inputs!$D$211) | I30: =$I$29*(Inputs!$H$183+Inputs!$D$211) | J30: =$J$29*(Inputs!$I$183+Inputs!$D$211)
B31: Bear: SG&A | C31: EGP | D31: =-(Inputs!$E$29+Inputs!$E$30) | E31: =$E$29*Inputs!$D$184 | F31: =$F$29*Inputs!$E$184 | G31: =$G$29*Inputs!$F$184 | H31: =$H$29*Inputs!$G$184 | I31: =$I$29*Inputs!$H$184 | J31: =$J$29*Inputs!$I$184
B32: Bear: Other operating income (net) | C32: EGP | D32: =Normalization!$D$13-Inputs!$E$26-Inputs!$E$29-Inputs!$E$30 | E32: =$E$29*Inputs!$D$185 | F32: =$F$29*Inputs!$E$185 | G32: =$G$29*Inputs!$F$185 | H32: =$H$29*Inputs!$G$185 | I32: =$I$29*Inputs!$H$185 | J32: =$J$29*Inputs!$I$185
B33: Bear: EBITDA | C33: EGP | D33: =$D$30-$D$31+$D$32 | E33: =$E$30-$E$31+$E$32 | F33: =$F$30-$F$31+$F$32 | G33: =$G$30-$G$31+$G$32 | H33: =$H$30-$H$31+$H$32 | I33: =$I$30-$I$31+$I$32 | J33: =$J$30-$J$31+$J$32
B34: Bear: Opening PP&E | C34: EGP | E34: =Inputs!$E$57 | F34: =$E$39 | G34: =$F$39 | H34: =$G$39 | I34: =$H$39 | J34: =$I$39
B35: Bear: Depreciation | C35: EGP | D35: =Inputs!$E$51 | E35: =IF(Inputs!$D$180="ppe_rollforward",Inputs!$D$187*$E$34,$E$29*Inputs!$D$186) | F35: =IF(Inputs!$D$180="ppe_rollforward",Inputs!$E$187*$F$34,$F$29*Inputs!$E$186) | G35: =IF(Inputs!$D$180="ppe_rollforward",Inputs!$F$187*$G$34,$G$29*Inputs!$F$186) | H35: =IF(Inputs!$D$180="ppe_rollforward",Inputs!$G$187*$H$34,$H$29*Inputs!$G$186) | I35: =IF(Inputs!$D$180="ppe_rollforward",Inputs!$H$187*$I$34,$I$29*Inputs!$H$186) | J35: =IF(Inputs!$D$180="ppe_rollforward",Inputs!$I$187*$J$34,$J$29*Inputs!$I$186)
B36: Bear: Amortization | C36: EGP | D36: =Inputs!$E$52 | E36: =IF(Inputs!$D$180="ppe_rollforward",$E$29*Inputs!$D$188,0) | F36: =IF(Inputs!$D$180="ppe_rollforward",$F$29*Inputs!$E$188,0) | G36: =IF(Inputs!$D$180="ppe_rollforward",$G$29*Inputs!$F$188,0) | H36: =IF(Inputs!$D$180="ppe_rollforward",$H$29*Inputs!$G$188,0) | I36: =IF(Inputs!$D$180="ppe_rollforward",$I$29*Inputs!$H$188,0) | J36: =IF(Inputs!$D$180="ppe_rollforward",$J$29*Inputs!$I$188,0)
B37: Bear: D&A | C37: EGP | D37: =$D$35+$D$36 | E37: =$E$35+$E$36 | F37: =$F$35+$F$36 | G37: =$G$35+$G$36 | H37: =$H$35+$H$36 | I37: =$I$35+$I$36 | J37: =$J$35+$J$36
B38: Bear: Capex | C38: EGP | D38: =-Inputs!$E$111 | E38: =IF(Inputs!$D$181="absolute",Inputs!$D$190,$E$29*Inputs!$D$189) | F38: =IF(Inputs!$D$181="absolute",Inputs!$E$190,$F$29*Inputs!$E$189) | G38: =IF(Inputs!$D$181="absolute",Inputs!$F$190,$G$29*Inputs!$F$189) | H38: =IF(Inputs!$D$181="absolute",Inputs!$G$190,$H$29*Inputs!$G$189) | I38: =IF(Inputs!$D$181="absolute",Inputs!$H$190,$I$29*Inputs!$H$189) | J38: =$J$29*Inputs!$I$189
B39: Bear: Closing PP&E | C39: EGP | D39: =Inputs!$E$57 | E39: =$E$34+$E$38-$E$35 | F39: =$F$34+$F$38-$F$35 | G39: =$G$34+$G$38-$G$35 | H39: =$H$34+$H$38-$H$35 | I39: =$I$34+$I$38-$I$35 | J39: =$J$34+$J$38-$J$35
B40: Bear: EBIT | C40: EGP | D40: =$D$33-$D$37 | E40: =$E$33-$E$37 | F40: =$F$33-$F$37 | G40: =$G$33-$G$37 | H40: =$H$33-$H$37 | I40: =$I$33-$I$37 | J40: =$J$33-$J$37
B41: Bear: Tax rate on EBIT | C41: % | D41: =Inputs!$D$133 | E41: =Inputs!$D$196 | F41: =Inputs!$E$196 | G41: =Inputs!$F$196 | H41: =Inputs!$G$196 | I41: =Inputs!$H$196 | J41: =Inputs!$I$196
B42: Bear: Tax on EBIT | C42: EGP | D42: =$D$40*$D$41 | E42: =$E$40*$E$41 | F42: =$F$40*$F$41 | G42: =$G$40*$G$41 | H42: =$H$40*$H$41 | I42: =$I$40*$I$41 | J42: =$J$40*$J$41
B43: Bear: NOPAT | C43: EGP | D43: =$D$40-$D$42 | E43: =$E$40-$E$42 | F43: =$F$40-$F$42 | G43: =$G$40-$G$42 | H43: =$H$40-$H$42 | I43: =$I$40-$I$42 | J43: =$J$40-$J$42
B44: Bear: Cash cost of sales | C44: EGP | D44: =$D$29*(1-((Inputs!$E$26+Inputs!$E$51+Inputs!$E$52)/$D$29)) | E44: =$E$29*(1-(Inputs!$D$183+Inputs!$D$211)) | F44: =$F$29*(1-(Inputs!$E$183+Inputs!$D$211)) | G44: =$G$29*(1-(Inputs!$F$183+Inputs!$D$211)) | H44: =$H$29*(1-(Inputs!$G$183+Inputs!$D$211)) | I44: =$I$29*(1-(Inputs!$H$183+Inputs!$D$211)) | J44: =$J$29*(1-(Inputs!$I$183+Inputs!$D$211))
B45: Bear: Accounts receivable | C45: EGP | D45: =Inputs!$E$67 | E45: =$E$29*Inputs!$D$191/Inputs!$D$18 | F45: =$F$29*Inputs!$E$191/Inputs!$D$18 | G45: =$G$29*Inputs!$F$191/Inputs!$D$18 | H45: =$H$29*Inputs!$G$191/Inputs!$D$18 | I45: =$I$29*Inputs!$H$191/Inputs!$D$18 | J45: =$J$29*Inputs!$I$191/Inputs!$D$18
B46: Bear: Inventory | C46: EGP | D46: =Inputs!$E$66 | E46: =$E$44*Inputs!$D$192/Inputs!$D$18 | F46: =$F$44*Inputs!$E$192/Inputs!$D$18 | G46: =$G$44*Inputs!$F$192/Inputs!$D$18 | H46: =$H$44*Inputs!$G$192/Inputs!$D$18 | I46: =$I$44*Inputs!$H$192/Inputs!$D$18 | J46: =$J$44*Inputs!$I$192/Inputs!$D$18
...

Sheet Sensitivity
B2: MOPCO: Sensitivity
B3: Value per share, 5 × 5 grids with the base case at the centre. Each cell is a full re-run in formulas: grids 1, 2 and 4 re-discount the model cash flows; grid 3 uses one mini operating model per cell (below).
B4: Blue = hardcoded input | Black = formula
B6: Grid 1 support: terminal-year FCFF by terminal growth
D7: g − 2 steps | E7: g − 1 step | F7: Base | G7: g + 1 step | H7: g + 2 steps | K7: Notes
B8: Terminal growth | C8: % | D8: =Inputs!$D$172+Inputs!$D$237*Inputs!$D$231 | E8: =Inputs!$D$172+Inputs!$E$237*Inputs!$D$231 | F8: =Inputs!$D$172+Inputs!$F$237*Inputs!$D$231 | G8: =Inputs!$D$172+Inputs!$G$237*Inputs!$D$231 | H8: =Inputs!$D$172+Inputs!$H$237*Inputs!$D$231
B9: Terminal-year revenue | C9: EGP | D9: ='Operating Model'!$I$9*(1+$D$8) | E9: ='Operating Model'!$I$9*(1+$E$8) | F9: ='Operating Model'!$I$9*(1+$F$8) | G9: ='Operating Model'!$I$9*(1+$G$8) | H9: ='Operating Model'!$I$9*(1+$H$8)
B10: EBITDA | C10: EGP | D10: =$D$9*(Inputs!$I$183-Inputs!$I$184+Inputs!$I$185) | E10: =$E$9*(Inputs!$I$183-Inputs!$I$184+Inputs!$I$185) | F10: =$F$9*(Inputs!$I$183-Inputs!$I$184+Inputs!$I$185) | G10: =$G$9*(Inputs!$I$183-Inputs!$I$184+Inputs!$I$185) | H10: =$H$9*(Inputs!$I$183-Inputs!$I$184+Inputs!$I$185)
B11: Depreciation | C11: EGP | D11: =IF(Inputs!$D$180="ppe_rollforward",Inputs!$I$187*'Operating Model'!$I$22,$D$9*Inputs!$I$186) | E11: =IF(Inputs!$D$180="ppe_rollforward",Inputs!$I$187*'Operating Model'!$I$22,$E$9*Inputs!$I$186) | F11: =IF(Inputs!$D$180="ppe_rollforward",Inputs!$I$187*'Operating Model'!$I$22,$F$9*Inputs!$I$186) | G11: =IF(Inputs!$D$180="ppe_rollforward",Inputs!$I$187*'Operating Model'!$I$22,$G$9*Inputs!$I$186) | H11: =IF(Inputs!$D$180="ppe_rollforward",Inputs!$I$187*'Operating Model'!$I$22,$H$9*Inputs!$I$186)
B12: Amortization | C12: EGP | D12: =IF(Inputs!$D$180="ppe_rollforward",$D$9*Inputs!$I$188,0) | E12: =IF(Inputs!$D$180="ppe_rollforward",$E$9*Inputs!$I$188,0) | F12: =IF(Inputs!$D$180="ppe_rollforward",$F$9*Inputs!$I$188,0) | G12: =IF(Inputs!$D$180="ppe_rollforward",$G$9*Inputs!$I$188,0) | H12: =IF(Inputs!$D$180="ppe_rollforward",$H$9*Inputs!$I$188,0)
B13: Capex | C13: EGP | D13: =$D$9*Inputs!$I$189 | E13: =$E$9*Inputs!$I$189 | F13: =$F$9*Inputs!$I$189 | G13: =$G$9*Inputs!$I$189 | H13: =$H$9*Inputs!$I$189
